E
======================================================================
ERROR: tests (unittest.loader._FailedTest)
----------------------------------------------------------------------
ImportError: Failed to import test module: tests
Traceback (most recent call last):
  File "/home/luizandre_tavares/.local/lib/python3.8/site-packages/django/db/backends/base/base.py", line 242, in _commit
    return self.connection.commit()
sqlite3.OperationalError: database is locked

The above exception was the direct cause of the following exception:

Traceback (most recent call last):
  File "/usr/lib/python3.8/unittest/loader.py", line 436, in _find_test_path
    module = self._get_module_from_name(name)
  File "/usr/lib/python3.8/unittest/loader.py", line 377, in _get_module_from_name
    __import__(name)
  File "/mnt/disks/data/forest500-backend copy/twitter/tests.py", line 292, in <module>
    tweetParse(tweet)
  File "/mnt/disks/data/forest500-backend copy/twitter/tests.py", line 74, in tweetParse
    user.urls.add(url)
  File "/home/luizandre_tavares/.local/lib/python3.8/site-packages/django/db/models/fields/related_descriptors.py", line 957, in add
    self._add_items(
  File "/home/luizandre_tavares/.local/lib/python3.8/site-packages/django/db/transaction.py", line 246, in __exit__
    connection.commit()
  File "/home/luizandre_tavares/.local/lib/python3.8/site-packages/django/utils/asyncio.py", line 26, in inner
    return func(*args, **kwargs)
  File "/home/luizandre_tavares/.local/lib/python3.8/site-packages/django/db/backends/base/base.py", line 266, in commit
    self._commit()
  File "/home/luizandre_tavares/.local/lib/python3.8/site-packages/django/db/backends/base/base.py", line 242, in _commit
    return self.connection.commit()
  File "/home/luizandre_tavares/.local/lib/python3.8/site-packages/django/db/utils.py", line 90, in __exit__
    raise dj_exc_value.with_traceback(traceback) from exc_value
  File "/home/luizandre_tavares/.local/lib/python3.8/site-packages/django/db/backends/base/base.py", line 242, in _commit
    return self.connection.commit()
django.db.utils.OperationalError: database is locked


----------------------------------------------------------------------
Ran 1 test in 0.004s

FAILED (errors=1)
